[2023-09-22T15:37:51.265+0000] {taskinstance.py:1157} INFO - Dependencies all met for dep_context=non-requeueable deps ti=<TaskInstance: my_dag.choose_best_model scheduled__2023-09-21T00:00:00+00:00 [queued]>
[2023-09-22T15:37:51.270+0000] {taskinstance.py:1157} INFO - Dependencies all met for dep_context=requeueable deps ti=<TaskInstance: my_dag.choose_best_model scheduled__2023-09-21T00:00:00+00:00 [queued]>
[2023-09-22T15:37:51.270+0000] {taskinstance.py:1359} INFO - Starting attempt 1 of 1
[2023-09-22T15:37:51.278+0000] {taskinstance.py:1380} INFO - Executing <Task(BranchPythonOperator): choose_best_model> on 2023-09-21 00:00:00+00:00
[2023-09-22T15:37:51.287+0000] {standard_task_runner.py:57} INFO - Started process 146 to run task
[2023-09-22T15:37:51.292+0000] {standard_task_runner.py:84} INFO - Running: ['***', 'tasks', 'run', 'my_dag', 'choose_best_model', 'scheduled__2023-09-21T00:00:00+00:00', '--job-id', '26', '--raw', '--subdir', 'DAGS_FOLDER/my_dag.py', '--cfg-path', '/tmp/tmpb89bqje0']
[2023-09-22T15:37:51.297+0000] {standard_task_runner.py:85} INFO - Job 26: Subtask choose_best_model
[2023-09-22T15:37:51.340+0000] {task_command.py:415} INFO - Running <TaskInstance: my_dag.choose_best_model scheduled__2023-09-21T00:00:00+00:00 [running]> on host 09f15e53a28d
[2023-09-22T15:37:51.397+0000] {taskinstance.py:1660} INFO - Exporting env vars: AIRFLOW_CTX_DAG_OWNER='***' AIRFLOW_CTX_DAG_ID='my_dag' AIRFLOW_CTX_TASK_ID='choose_best_model' AIRFLOW_CTX_EXECUTION_DATE='2023-09-21T00:00:00+00:00' AIRFLOW_CTX_TRY_NUMBER='1' AIRFLOW_CTX_DAG_RUN_ID='scheduled__2023-09-21T00:00:00+00:00'
[2023-09-22T15:37:51.399+0000] {taskinstance.py:1935} ERROR - Task failed with exception
Traceback (most recent call last):
  File "/home/airflow/.local/lib/python3.8/site-packages/airflow/operators/python.py", line 226, in execute
    branch = super().execute(context)
  File "/home/airflow/.local/lib/python3.8/site-packages/airflow/operators/python.py", line 192, in execute
    return_value = self.execute_callable()
  File "/home/airflow/.local/lib/python3.8/site-packages/airflow/operators/python.py", line 209, in execute_callable
    return self.python_callable(*self.op_args, **self.op_kwargs)
  File "/opt/airflow/dags/my_dag.py", line 9, in _choose_best_model
    accuracies=ti.xcom_pull(task_id=[
  File "/home/airflow/.local/lib/python3.8/site-packages/airflow/utils/session.py", line 77, in wrapper
    return func(*args, session=session, **kwargs)
TypeError: xcom_pull() got an unexpected keyword argument 'task_id'
[2023-09-22T15:37:51.407+0000] {taskinstance.py:1398} INFO - Marking task as FAILED. dag_id=my_dag, task_id=choose_best_model, execution_date=20230921T000000, start_date=20230922T153751, end_date=20230922T153751
[2023-09-22T15:37:51.416+0000] {standard_task_runner.py:104} ERROR - Failed to execute job 26 for task choose_best_model (xcom_pull() got an unexpected keyword argument 'task_id'; 146)
[2023-09-22T15:37:51.425+0000] {local_task_job_runner.py:228} INFO - Task exited with return code 1
[2023-09-22T15:37:51.450+0000] {taskinstance.py:2776} INFO - 0 downstream tasks scheduled from follow-on schedule check
